<mujoco model="hopper">
  <compiler angle="degree" inertiafromgeom="true"/>
  <default>
    <joint armature="1" damping="1" limited="true"/>
    <geom conaffinity="1" condim="1" contype="1" margin="0.001" material="geom" rgba="0.8 0.6 .4 1" solimp=".8 .8 .01" solref=".02 1"/>
    <motor ctrllimited="true" ctrlrange="-.4 .4"/>
  </default>
  <option integrator="RK4" timestep="0.002"/>
  <visual>
    <map znear="0.02"/>
  </visual>
  <worldbody>
    <light cutoff="100" diffuse="1 1 1" dir="-0 0 -1.3" directional="true" exponent="1" pos="0 0 1.3" specular=".1 .1 .1"/>
    <geom conaffinity="1" condim="3" name="floor" pos="0 0 0" rgba="0.8 0.9 0.8 1" size="20 20 .125" type="plane" material="MatPlane"/>
    <body name="0" pos="0 0 1.6">
      <camera name="track" mode="trackcom" pos="0 -3 0.25" xyaxes="1 0 0 0 0 1"/>
      <joint armature="0" axis="1 0 0" damping="0" limited="false" name="rootx" pos="0 0 0" stiffness="0" type="slide"/>
      <joint armature="0" axis="0 0 1" damping="0" limited="false" name="rootz" pos="0 0 0" ref="1.25" stiffness="0" type="slide"/>
      <joint armature="0" axis="0 1 0" damping="0" limited="false" name="0_joint" pos="0 0 0" stiffness="0" type="hinge"/>
      <geom friction="0.9" fromto="0 0 0 0 0 0.2" size="0.05" type="capsule" rgba="0.9 0.9 .4 1"/>
      <body name="1" pos="0 0 0">
        <joint axis="0 -1 0" name="1_joint" pos="0 0 0" range="-50 50" type="hinge"/>
        <geom friction="0.9" fromto="0 0 0 0 0 -0.2" size="0.04" type="capsule"/>
      </body>
    </body>
  </worldbody>
  <actuator>
    <motor ctrllimited="true" ctrlrange="-1.0 1.0" gear="150" joint="1_joint" name="1_joint"/>
  </actuator>
  <asset>
    <texture type="skybox" builtin="gradient" rgb1=".4 .5 .6" rgb2="0 0 0" width="100" height="100"/>
    <texture builtin="flat" height="1278" mark="cross" markrgb="1 1 1" name="texgeom" random="0.01" rgb1="0.8 0.6 0.4" rgb2="0.8 0.6 0.4" type="cube" width="127"/>
    <texture builtin="checker" height="100" name="texplane" rgb1="0.38 0.48 0.38" rgb2="0.4 0.5 0.4" type="2d" width="100"/>
    <material name="MatPlane" reflectance="0.5" shininess="1" specular="1" texrepeat="60 60" texture="texplane"/>
    <material name="geom" texture="texgeom" texuniform="true"/>
  </asset>
</mujoco>
